2021-06-25T12:16:11|CRITICAL|root|Unhandled exception:Traceback (most recent call last):
  File "C:\Users\laboratorio\anaconda3\envs\DMD\lib\site-packages\ScopeFoundry\hardware.py", line 160, in <lambda>
    op_button.clicked.connect(lambda checked, f=op_func: f())
  File "C:\Programmi laboratorio\Python\ScopeFoundryProjects\VialuxDMD_ScopeFoundry\DMD_hw.py", line 65, in generate_random_patterns
    self.vialux.set_timing(Till, Tdead)
  File "C:\Programmi laboratorio\Python\ScopeFoundryProjects\VialuxDMD_ScopeFoundry\DMD_device.py", line 59, in set_timing
    triggerInDelay=None)               #length of trigger signal [us], default=0
  File "C:\Programmi laboratorio\Python\VialuxDMDlibraries\ALP4.py", line 699, in SetTiming
    'Cannot set timing.')
  File "C:\Programmi laboratorio\Python\VialuxDMDlibraries\ALP4.py", line 395, in _checkError
    raise ALPError(returnValue)
ALP4.ALPError: One of the parameters is invalid.

