2021-06-25T11:53:37|CRITICAL|root|Unhandled exception:Traceback (most recent call last):
  File "C:\Users\laboratorio\anaconda3\envs\DMD\lib\site-packages\ScopeFoundry\hardware.py", line 208, in enable_connection
    raise err
  File "C:\Users\laboratorio\anaconda3\envs\DMD\lib\site-packages\ScopeFoundry\hardware.py", line 204, in enable_connection
    self.connect()
  File "C:\Programmi laboratorio\Python\ScopeFoundryProjects\VialuxDMD_ScopeFoundry\DMD_hw.py", line 35, in connect
    self.avail_memory.hardware_read_func = self.vialux.get_avail_memory
AttributeError: 'VialuxDmdDevice' object has no attribute 'get_avail_memory'

