2021-07-05T14:52:00|CRITICAL|root|Unhandled exception:Traceback (most recent call last):
  File "C:\Users\laboratorio\anaconda3\envs\DMD\lib\site-packages\ScopeFoundry\hardware.py", line 160, in <lambda>
    op_button.clicked.connect(lambda checked, f=op_func: f())
  File "C:\Programmi laboratorio\Python\ScopeFoundryProjects\VialuxDMD_ScopeFoundry\DMD_hw.py", line 140, in free_memory
    self.settings['avail_memory'] = self.vialux.get_available_memory()
  File "C:\Programmi laboratorio\Python\ScopeFoundryProjects\VialuxDMD_ScopeFoundry\DMD_device.py", line 35, in get_available_memory
    return str(self.dmd.DevInquire(ALP_AVAIL_MEMORY))
  File "C:\Programmi laboratorio\Python\VialuxDMDlibraries\ALP4.py", line 729, in DevInquire
    self._checkError(self._ALPLib.AlpDevInquire(self.ALP_ID, inquireType, ct.byref(ret)), 'Error sending request.')
AttributeError: 'ALP4' object has no attribute '_ALPLib'

2021-07-05T14:52:09|CRITICAL|root|Unhandled exception:Traceback (most recent call last):
  File "C:\Users\laboratorio\anaconda3\envs\DMD\lib\site-packages\ScopeFoundry\hardware.py", line 160, in <lambda>
    op_button.clicked.connect(lambda checked, f=op_func: f())
  File "C:\Programmi laboratorio\Python\ScopeFoundryProjects\VialuxDMD_ScopeFoundry\DMD_hw.py", line 135, in free_sequence
    self.vialux.free_sequence()
  File "C:\Programmi laboratorio\Python\ScopeFoundryProjects\VialuxDMD_ScopeFoundry\DMD_device.py", line 98, in free_sequence
    self.dmd.FreeSeq()
  File "C:\Programmi laboratorio\Python\VialuxDMDlibraries\ALP4.py", line 981, in FreeSeq
    self._checkError(self._ALPLib.AlpSeqFree(self.ALP_ID, SequenceId), 'Unable to free the image sequence.',
AttributeError: 'ALP4' object has no attribute '_ALPLib'

2021-07-05T14:52:14|CRITICAL|root|Unhandled exception:Traceback (most recent call last):
  File "C:\Users\laboratorio\anaconda3\envs\DMD\lib\site-packages\ScopeFoundry\hardware.py", line 219, in enable_connection
    raise err
  File "C:\Users\laboratorio\anaconda3\envs\DMD\lib\site-packages\ScopeFoundry\hardware.py", line 212, in enable_connection
    self.disconnect()
  File "C:\Programmi laboratorio\Python\ScopeFoundryProjects\VialuxDMD_ScopeFoundry\DMD_hw.py", line 65, in disconnect
    self.vialux.close()
  File "C:\Programmi laboratorio\Python\ScopeFoundryProjects\VialuxDMD_ScopeFoundry\DMD_device.py", line 104, in close
    self.dmd.Halt()
  File "C:\Programmi laboratorio\Python\VialuxDMDlibraries\ALP4.py", line 1029, in Halt
    self._checkError(self._ALPLib.AlpDevHalt(self.ALP_ID), 'Cannot stop device.')
AttributeError: 'ALP4' object has no attribute '_ALPLib'

2021-07-05T14:52:53|CRITICAL|root|Unhandled exception:Traceback (most recent call last):
  File "C:\Users\laboratorio\anaconda3\envs\DMD\lib\site-packages\ScopeFoundry\hardware.py", line 160, in <lambda>
    op_button.clicked.connect(lambda checked, f=op_func: f())
  File "C:\Programmi laboratorio\Python\ScopeFoundryProjects\VialuxDMD_ScopeFoundry\DMD_hw.py", line 135, in free_sequence
    self.vialux.free_sequence()
  File "C:\Programmi laboratorio\Python\ScopeFoundryProjects\VialuxDMD_ScopeFoundry\DMD_device.py", line 98, in free_sequence
    self.dmd.FreeSeq()
  File "C:\Programmi laboratorio\Python\VialuxDMDlibraries\ALP4.py", line 980, in FreeSeq
    self.Seqs.remove(SequenceId)  # Removes the last SequenceId from sequence list
ValueError: list.remove(x): x not in list

2021-07-05T14:53:00|CRITICAL|root|Unhandled exception:Traceback (most recent call last):
  File "C:\Users\laboratorio\anaconda3\envs\DMD\lib\site-packages\ScopeFoundry\hardware.py", line 160, in <lambda>
    op_button.clicked.connect(lambda checked, f=op_func: f())
  File "C:\Programmi laboratorio\Python\ScopeFoundryProjects\VialuxDMD_ScopeFoundry\DMD_hw.py", line 140, in free_memory
    self.settings['avail_memory'] = self.vialux.get_available_memory()
  File "C:\Programmi laboratorio\Python\ScopeFoundryProjects\VialuxDMD_ScopeFoundry\DMD_device.py", line 35, in get_available_memory
    return str(self.dmd.DevInquire(ALP_AVAIL_MEMORY))
  File "C:\Programmi laboratorio\Python\VialuxDMDlibraries\ALP4.py", line 729, in DevInquire
    self._checkError(self._ALPLib.AlpDevInquire(self.ALP_ID, inquireType, ct.byref(ret)), 'Error sending request.')
AttributeError: 'ALP4' object has no attribute '_ALPLib'

2021-07-05T14:53:06|CRITICAL|root|Unhandled exception:Traceback (most recent call last):
  File "C:\Users\laboratorio\anaconda3\envs\DMD\lib\site-packages\ScopeFoundry\hardware.py", line 219, in enable_connection
    raise err
  File "C:\Users\laboratorio\anaconda3\envs\DMD\lib\site-packages\ScopeFoundry\hardware.py", line 212, in enable_connection
    self.disconnect()
  File "C:\Programmi laboratorio\Python\ScopeFoundryProjects\VialuxDMD_ScopeFoundry\DMD_hw.py", line 65, in disconnect
    self.vialux.close()
  File "C:\Programmi laboratorio\Python\ScopeFoundryProjects\VialuxDMD_ScopeFoundry\DMD_device.py", line 104, in close
    self.dmd.Halt()
  File "C:\Programmi laboratorio\Python\VialuxDMDlibraries\ALP4.py", line 1029, in Halt
    self._checkError(self._ALPLib.AlpDevHalt(self.ALP_ID), 'Cannot stop device.')
AttributeError: 'ALP4' object has no attribute '_ALPLib'

2021-07-05T15:06:20|ERROR|modulated_app|tried to disconnect VialuxDmdHW: 'ALP4' object has no attribute '_ALPLib'
