2021-07-07T15:52:27|CRITICAL|root|Unhandled exception:Traceback (most recent call last):
  File "C:\Users\laboratorio\anaconda3\envs\DMD\lib\site-packages\ScopeFoundry\hardware.py", line 208, in enable_connection
    raise err
  File "C:\Users\laboratorio\anaconda3\envs\DMD\lib\site-packages\ScopeFoundry\hardware.py", line 204, in enable_connection
    self.connect()
  File "C:\Programmi laboratorio\Python\ScopeFoundryProjects\VialuxDMD_ScopeFoundry\DMD_hw.py", line 59, in connect
    self.synch_pulse_width_max.hardware_set_func = self.set_timing_limits
AttributeError: 'VialuxDmdHW' object has no attribute 'synch_pulse_width_max'

